{"ts": "2025-08-21T06:18:37.153750Z", "level": "INFO", "msg": "Starting app", "logger": "microbiome", "app": "Microbiome XAI Chatbot", "r": {"r_found": true, "r_path": "C:\\Program Files\\R\\R-4.4.0\\bin\\R.exe", "infinte_loaded": true}}
{"ts": "2025-08-21T13:59:25.570347Z", "level": "INFO", "msg": "Starting app", "logger": "microbiome", "app": "Microbiome XAI Chatbot", "r": {"r_found": true, "r_path": "C:\\\\Program Files\\\\R\\\\R-4.4.0\\\\bin\\\\R.exe", "infinte_loaded": true}}
{"ts": "2025-08-21T13:59:30.108639Z", "level": "ERROR", "msg": "Unhandled exception", "logger": "microbiome", "corr": "90447d54", "trace": "Traceback (most recent call last):\n  File \"C:\\Users\\Lenovo\\AppData\\Roaming\\Python\\Python39\\site-packages\\flask\\app.py\", line 1484, in full_dispatch_request\n    rv = self.dispatch_request()\n  File \"C:\\Users\\Lenovo\\AppData\\Roaming\\Python\\Python39\\site-packages\\flask\\app.py\", line 1458, in dispatch_request\n    self.raise_routing_exception(req)\n  File \"C:\\Users\\Lenovo\\AppData\\Roaming\\Python\\Python39\\site-packages\\flask\\app.py\", line 1440, in raise_routing_exception\n    raise request.routing_exception  # type: ignore\n  File \"C:\\Users\\Lenovo\\AppData\\Roaming\\Python\\Python39\\site-packages\\flask\\ctx.py\", line 353, in match_request\n    result = self.url_adapter.match(return_rule=True)  # type: ignore\n  File \"C:\\Users\\Lenovo\\AppData\\Roaming\\Python\\Python39\\site-packages\\werkzeug\\routing\\map.py\", line 655, in match\n    raise NotFound() from None\nwerkzeug.exceptions.NotFound: 404 Not Found: The requested URL was not found on the server. If you entered the URL manually please check your spelling and try again.\n"}
{"ts": "2025-08-21T13:59:41.089284Z", "level": "ERROR", "msg": "Unhandled exception", "logger": "microbiome", "corr": "7a151371", "trace": "Traceback (most recent call last):\n  File \"C:\\Users\\Lenovo\\AppData\\Roaming\\Python\\Python39\\site-packages\\flask\\app.py\", line 1484, in full_dispatch_request\n    rv = self.dispatch_request()\n  File \"C:\\Users\\Lenovo\\AppData\\Roaming\\Python\\Python39\\site-packages\\flask\\app.py\", line 1469, in dispatch_request\n    return self.ensure_sync(self.view_functions[rule.endpoint])(**view_args)\n  File \"C:\\MicrobiomeBot\\Microbot-\\microbiome_xai_chatbot_pro_v7_1.py\", line 745, in chat\n    m = re.search(r\"which\\\\s+otu[_\\\\- ]?id\\\\s+has\\\\s+species[_\\\\- ]?name\\\\s+([a-z0-9_\\\\-]+)\", tlow)\n  File \"C:\\Users\\Lenovo\\AppData\\Local\\Programs\\Python\\Python39\\lib\\re.py\", line 201, in search\n    return _compile(pattern, flags).search(string)\n  File \"C:\\Users\\Lenovo\\AppData\\Local\\Programs\\Python\\Python39\\lib\\re.py\", line 304, in _compile\n    p = sre_compile.compile(pattern, flags)\n  File \"C:\\Users\\Lenovo\\AppData\\Local\\Programs\\Python\\Python39\\lib\\sre_compile.py\", line 788, in compile\n    p = sre_parse.parse(p, flags)\n  File \"C:\\Users\\Lenovo\\AppData\\Local\\Programs\\Python\\Python39\\lib\\sre_parse.py\", line 955, in parse\n    p = _parse_sub(source, state, flags & SRE_FLAG_VERBOSE, 0)\n  File \"C:\\Users\\Lenovo\\AppData\\Local\\Programs\\Python\\Python39\\lib\\sre_parse.py\", line 444, in _parse_sub\n    itemsappend(_parse(source, state, verbose, nested + 1,\n  File \"C:\\Users\\Lenovo\\AppData\\Local\\Programs\\Python\\Python39\\lib\\sre_parse.py\", line 599, in _parse\n    raise source.error(msg, len(this) + 1 + len(that))\nre.error: bad character range \\\\-  at position 14\n"}
{"ts": "2025-08-21T13:59:49.737491Z", "level": "ERROR", "msg": "Unhandled exception", "logger": "microbiome", "corr": "406ace3b", "trace": "Traceback (most recent call last):\n  File \"C:\\Users\\Lenovo\\AppData\\Roaming\\Python\\Python39\\site-packages\\flask\\app.py\", line 1484, in full_dispatch_request\n    rv = self.dispatch_request()\n  File \"C:\\Users\\Lenovo\\AppData\\Roaming\\Python\\Python39\\site-packages\\flask\\app.py\", line 1458, in dispatch_request\n    self.raise_routing_exception(req)\n  File \"C:\\Users\\Lenovo\\AppData\\Roaming\\Python\\Python39\\site-packages\\flask\\app.py\", line 1440, in raise_routing_exception\n    raise request.routing_exception  # type: ignore\n  File \"C:\\Users\\Lenovo\\AppData\\Roaming\\Python\\Python39\\site-packages\\flask\\ctx.py\", line 353, in match_request\n    result = self.url_adapter.match(return_rule=True)  # type: ignore\n  File \"C:\\Users\\Lenovo\\AppData\\Roaming\\Python\\Python39\\site-packages\\werkzeug\\routing\\map.py\", line 655, in match\n    raise NotFound() from None\nwerkzeug.exceptions.NotFound: 404 Not Found: The requested URL was not found on the server. If you entered the URL manually please check your spelling and try again.\n"}
{"ts": "2025-08-21T14:00:03.670886Z", "level": "ERROR", "msg": "Unhandled exception", "logger": "microbiome", "corr": "6d19b6e6", "trace": "Traceback (most recent call last):\n  File \"C:\\Users\\Lenovo\\AppData\\Roaming\\Python\\Python39\\site-packages\\flask\\app.py\", line 1484, in full_dispatch_request\n    rv = self.dispatch_request()\n  File \"C:\\Users\\Lenovo\\AppData\\Roaming\\Python\\Python39\\site-packages\\flask\\app.py\", line 1469, in dispatch_request\n    return self.ensure_sync(self.view_functions[rule.endpoint])(**view_args)\n  File \"C:\\MicrobiomeBot\\Microbot-\\microbiome_xai_chatbot_pro_v7_1.py\", line 745, in chat\n    m = re.search(r\"which\\\\s+otu[_\\\\- ]?id\\\\s+has\\\\s+species[_\\\\- ]?name\\\\s+([a-z0-9_\\\\-]+)\", tlow)\n  File \"C:\\Users\\Lenovo\\AppData\\Local\\Programs\\Python\\Python39\\lib\\re.py\", line 201, in search\n    return _compile(pattern, flags).search(string)\n  File \"C:\\Users\\Lenovo\\AppData\\Local\\Programs\\Python\\Python39\\lib\\re.py\", line 304, in _compile\n    p = sre_compile.compile(pattern, flags)\n  File \"C:\\Users\\Lenovo\\AppData\\Local\\Programs\\Python\\Python39\\lib\\sre_compile.py\", line 788, in compile\n    p = sre_parse.parse(p, flags)\n  File \"C:\\Users\\Lenovo\\AppData\\Local\\Programs\\Python\\Python39\\lib\\sre_parse.py\", line 955, in parse\n    p = _parse_sub(source, state, flags & SRE_FLAG_VERBOSE, 0)\n  File \"C:\\Users\\Lenovo\\AppData\\Local\\Programs\\Python\\Python39\\lib\\sre_parse.py\", line 444, in _parse_sub\n    itemsappend(_parse(source, state, verbose, nested + 1,\n  File \"C:\\Users\\Lenovo\\AppData\\Local\\Programs\\Python\\Python39\\lib\\sre_parse.py\", line 599, in _parse\n    raise source.error(msg, len(this) + 1 + len(that))\nre.error: bad character range \\\\-  at position 14\n"}
{"ts": "2025-08-21T14:00:07.989278Z", "level": "ERROR", "msg": "Unhandled exception", "logger": "microbiome", "corr": "14b32606", "trace": "Traceback (most recent call last):\n  File \"C:\\Users\\Lenovo\\AppData\\Roaming\\Python\\Python39\\site-packages\\flask\\app.py\", line 1484, in full_dispatch_request\n    rv = self.dispatch_request()\n  File \"C:\\Users\\Lenovo\\AppData\\Roaming\\Python\\Python39\\site-packages\\flask\\app.py\", line 1469, in dispatch_request\n    return self.ensure_sync(self.view_functions[rule.endpoint])(**view_args)\n  File \"C:\\MicrobiomeBot\\Microbot-\\microbiome_xai_chatbot_pro_v7_1.py\", line 745, in chat\n    m = re.search(r\"which\\\\s+otu[_\\\\- ]?id\\\\s+has\\\\s+species[_\\\\- ]?name\\\\s+([a-z0-9_\\\\-]+)\", tlow)\n  File \"C:\\Users\\Lenovo\\AppData\\Local\\Programs\\Python\\Python39\\lib\\re.py\", line 201, in search\n    return _compile(pattern, flags).search(string)\n  File \"C:\\Users\\Lenovo\\AppData\\Local\\Programs\\Python\\Python39\\lib\\re.py\", line 304, in _compile\n    p = sre_compile.compile(pattern, flags)\n  File \"C:\\Users\\Lenovo\\AppData\\Local\\Programs\\Python\\Python39\\lib\\sre_compile.py\", line 788, in compile\n    p = sre_parse.parse(p, flags)\n  File \"C:\\Users\\Lenovo\\AppData\\Local\\Programs\\Python\\Python39\\lib\\sre_parse.py\", line 955, in parse\n    p = _parse_sub(source, state, flags & SRE_FLAG_VERBOSE, 0)\n  File \"C:\\Users\\Lenovo\\AppData\\Local\\Programs\\Python\\Python39\\lib\\sre_parse.py\", line 444, in _parse_sub\n    itemsappend(_parse(source, state, verbose, nested + 1,\n  File \"C:\\Users\\Lenovo\\AppData\\Local\\Programs\\Python\\Python39\\lib\\sre_parse.py\", line 599, in _parse\n    raise source.error(msg, len(this) + 1 + len(that))\nre.error: bad character range \\\\-  at position 14\n"}
{"ts": "2025-08-21T14:40:13.435845Z", "level": "INFO", "msg": "Starting backend v6.3"}
{"ts": "2025-08-21T14:53:19.409621Z", "level": "INFO", "msg": "Starting backend v6.3"}
